Workbook
Name Filename: Bitacora!#REF!
Name Filename: #REF!

Sheet Maestro
A1: On Hold | C1: BL ERRADO | E1: COMERCIAL | H1: POD | I1: Código de puerto
A2: Released | C2: CAMBIO DE CLIENTE | E2: GESTOR DOCUMENTAL | H2: USPHL | I2: 4000224852
C3: CAMBIO DE CONSIGNEE | E3: NAVIERA | H3: USLGB | I3: 4000224850
C4: CAMBIO DE PRECIO | E4: OPERADOR LOGISTICO | H4: USMIA | I4: 4000287585
C5: CAMBIO DE PUERTO DE DESTINO | E5: SENASA | H5: USNTD | I5: 4000224850
C6: CARTAS ERRADAS | E6: SOP | H6: USLAX | I6: 4000224850
C7: CERTIFICADO ORGANICO ERRADO | E7: TRADING | H7: USGLC | I7: 4000224852
C8: CO ERRADO | E8: TERCERO
C9: DATOS ERRADOS EN CONSOLIDADOS (JORDIE/TALSA) | E9: TI
C10: DEMORA EN LA EMISIÓN DEL CERTIFICADO FITOSANITARIO | E10: EXPORTACIONES
C11: ENVIO DE SET DOCUMENTAL TARDIO | E11: FOOD SAFETY
C12: FITOSANITARIO ERRADO | E12: NOMINACIÓN
C13: ISF ERRADO | E13: GESTOR SENASA
C14: ROLEO DE NAVE
C15: OTROS
C16: DEMORA EN LA FACTURA
C17: DEMORA EN PAGO DE BL FLETADO
C18: COI ERRADO
C19: PENDIENTE PHYTO
C20: PENDIENTE FULLDOC NWT
C21: DEMORA EN ENVIO DHL FAMEX | H21: ISF
C22: BL A DESTIEMPO | H22: X | I22: FECHA
H23: NO | I23: 3 DIAS ANTES AMARILLO = PENDIENTE
H24: NO | I24: 2 DIAS ANTES NARANJA = URGENTE
H25: NO | I25: 1 DIA ANTES ROJO = MUY URGENTE
H26: SI | I26: ENVIADO = VERDE

Sheet Bitacora
A1: Key | B1: WK | C1: Fecha de carga | D1: WK Arribo | E1: Mercado | F1: POD | G1: Origen | H1: Exportador | I1: Clase Expedición | J1: Especie | K1: Manejo | L1: N° PO | M1: Contenedor | N1: Consignee | O1: Cliente | P1: Line | Q1: Nave + Viaje | R1: ETD Real | S1: ETA Real | T1: OL | U1: ETA Doc | V1: ETD Doc | W1: ATA DOC | X1: % OBTENCIÓN | Y1: % ANTICIPACIÓN | Z1: GUÍA DHL | AA1: PHYTO | AB1: CARTAS | AC1: INVOICE | AD1: BL / Gaérea | AE1: PL | AF1: ISF | AG1: COI | AH1: CO | AI1: ISF Status | AJ1: FULL DOCUMENT | AK1: Columna1 | AL1: Responsable | AM1: Clase de Exportador | AN1: Status Documental | AO1: Status Container | AP1: Release Date | AQ1: Container Status | AR1: Comments (Status container)
A2: PO00000050459HFPEARANCONV497-24313730 | B2: 19 | C2: 46150 | D2: 20 | E2: LATAM | F2: BOG | G2: PE | H2: HFPE | I2: AIR | J2: ARAN | K2: CONV | L2: PO00000050459 | M2: 497-24313730 | N2: HORTIFRUT COLOMBIA SAS | O2: HORTIFRUT COLOMBIA SAS | P2: AERCARIBE | Q2: 24 | R2: 46154 | S2: 46154 | T2: HELLMANN | U2: =+IF(Bitacora_2[[#This Row],[ATA DOC]]<>"",Bitacora_2[[#This Row],[ATA DOC]], IF(Bitacora_2[[#This Row],[Clase Expedición]]="AIR",Bitacora_2[[#This Row],[ETD Real]], IF(AND(Bitacora_2[[#This Row],[Clase Expedición]]="SEA",Bitacora_2[[#This Row],[Mercado]]="LATAM"), Bitacora_2[[#This Row],[ETD Real]]+3, IF(AND(Bitacora_2[[#This Row],[Clase Expedición]]="SEA",Bitacora_2[[#This Row],[Mercado]]="EUROPE"), Bitacora_2[[#This Row],[ETD Real]]+8, IF(AND(Bitacora_2[[#This Row],[Clase Expedición]]="SEA",Bitacora_2[[#This Row],[Mercado]]="UK"), Bitacora_2[[#This Row],[ETD Real]]+11, IF(AND(Bitacora_2[[#This Row],[Clase Expedición]]="SEA",OR(Bitacora_2[[#This Row],[Mercado]]="ASIA",Bitacora_2[[#This Row],[Mercado]]="ASIA CN + HK")), Bitacora_2[[#This Row],[ETD Real]]+14, IF(AND(Bitacora_2[[#This Row],[Clase Expedición]]="SEA",OR(Bitacora_2[[#This Row],[Mercado]]="US EAST",Bitacora_2[[#This Row],[Mercado]]="US WEST",Bitacora_2[[#This Row],[Mercado]]="US SOUTH")), Bitacora_2[[#This Row],[ETD Real]]+8,""))))))) -> 46154 | X2: =IF(OR(Bitacora_2[[#This Row],[ETD Real]]="",Bitacora_2[[#This Row],[ETD Doc]]=""),"",Bitacora_2[[#This Row],[ETD Doc]]-Bitacora_2[[#This Row],[ETD Real]]) | Y2: =IF(OR(Bitacora_2[[#This Row],[ATA DOC]]="",Bitacora_2[[#This Row],[ETA Real]]=""),"",Bitacora_2[[#This Row],[ETA Real]]-Bitacora_2[[#This Row],[ATA DOC]]) | AI2: =IF(AND(OR(E2="US EAST",E2="US WEST",E2="US SOUTH"),I2="SEA",Bitacora_2[[#This Row],[ETD Real]]-TODAY()>=3,Bitacora_2[[#This Row],[ISF]]<>"X"),"Pending", IF(AND(OR(E2="US EAST",E2="US WEST",E2="US SOUTH"),I2="SEA",Bitacora_2[[#This Row],[ETD Real]]-TODAY()=2,Bitacora_2[[#This Row],[ISF]]<>"X"),"Urgente", IF(AND(OR(E2="US EAST",E2="US WEST",E2="US SOUTH"),I2="SEA",Bitacora_2[[#This Row],[ETD Real]]-TODAY()<=1,Bitacora_2[[#This Row],[ISF]]<>"X"),"Muy Urgente", IF(AND(OR(E2="US EAST",E2="US WEST",E2="US SOUTH"),I2="SEA",Bitacora_2[[#This Row],[ISF]]="X"),"Sent","")))) | AJ2: =IF(AND(OR(Bitacora_2[[#This Row],[Clase Expedición]]="AIR",Bitacora_2[[#This Row],[Clase Expedición]]="TRK")),"Complete", IF(AND(Bitacora_2[[#This Row],[Mercado]]="LATAM",COUNTA(Bitacora_2[[#This Row],[PHYTO]:[ISF]],Bitacora_2[[#This Row],[CO]])=7,Bitacora_2[[#This Row],[Clase Expedición]]<>"TRK"), "Complete", IF(AND(Bitacora_2[[#This Row],[Mercado]]="LATAM",COUNTA(Bitacora_2[[#This Row],[PHYTO]:[PL ]],Bitacora_2[[#This Row],[CO]])=6,Bitacora_2[[#This Row],[Clase Expedición]]="SEA"), "Complete", IF(AND(OR(Bitacora_2[[#This Row],[Mercado]]="EUROPE",Bitacora_2[[#This Row],[Mercado]]="UK"),COUNTA(Bitacora_2[[#This Row],[PHYTO]],Bitacora_2[[#This Row],[INVOICE]:[PL ]],Bitacora_2[[#This Row],[COI]])=5,Bitacora_2[[#This Row],[Clase Expedición]]="SEA",Bitacora_2[[#This Row],[Manejo]]="ORG"), "Complete", IF(AND(OR(Bitacora_2[[#This Row],[Mercado]]="EUROPE",Bitacora_2[[#This Row],[Mercado]]="UK"),COUNTA(Bitacora_2[[#This Row],[PHYTO]],Bitacora_2[[#This Row],[INVOICE]:[PL ]])=4,Bitacora_2[[#This Row],[Clase Expedición]]="SEA",Bitacora_2[[#This Row],[Manejo]]="CONV"), "Complete", IF(AND(OR(Bitacora_2[[#This Row],[Mercado]]="US WEST",Bitacora_2[[#This Row],[Mercado]]="US EAST",Bitacora_2[[#This Row],[Mercado]]="US SOUTH"),COUNTA(Bitacora_2[[#This Row],[PHYTO]:[ISF]],Bitacora_2[[#This Row],[CO]])=7,Bitacora_2[[#This Row],[Clase Expedición]]="SEA",Bitacora_2[[#This Row],[Exportador]]="ECHF"), "Complete", IF(AND(OR(Bitacora_2[[#This Row],[Mercado]]="US WEST",Bitacora_2[[#This Row],[Mercado]]="US EAST",Bitacora_2[[#This Row],[Mercado]]="US SOUTH"),COUNTA(Bitacora_2[[#This Row],[PHYTO]:[ISF]])=6,Bitacora_2[[#This Row],[Clase Expedición]]="SEA",Bitacora_2[[#This Row],[Exportador]]<>"ECHF"), "Complete", IF(AND(OR(Bitacora_2[[#This Row],[Mercado]]="ASIA",Bitacora_2[[#This Row],[Mercado]]="ASIA CN + HK"),COUNTA(Bitacora_2[[#This Row],[PHYTO]:[PL ]],Bitacora_2[[#This Row],[CO]])=6), "Complete","Incomplete")))))))) -> Complete | AM2: =+IF(OR(Bitacora_2[[#This Row],[Exportador]]="INVERSIONES JORDIE",Bitacora_2[[#This Row],[Exportador]]="TAL S.A."), "Tercero", "Propio") -> Propio | AN2: =IF(AND(Bitacora_2[[#This Row],[Clase Expedición]]="AIR",OR(Bitacora_2[[#This Row],[Mercado]]="US EAST",Bitacora_2[[#This Row],[Mercado]]="US WEST",Bitacora_2[[#This Row],[Mercado]]="US SOUTH")),IF(Bitacora_2[[#This Row],[ETD Doc]]<>"","Delivered","Pending"), IF(Bitacora_2[[#This Row],[Clase Expedición]]="AIR","Delivered", IF(AND(Bitacora_2[[#This Row],[ETD Doc]]="",Bitacora_2[[#This Row],[ATA DOC]]=""),"Pending", IF(AND(Bitacora_2[[#This Row],[ETD Doc]]<>"",Bitacora_2[[#This Row],[ATA DOC]]=""),"In transit", IF(AND(Bitacora_2[[#This Row],[ETD Doc]]<>"",Bitacora_2[[#This Row],[ATA DOC]]<>""),"Delivered",""))))) -> Delivered | AQ2: =IF(I2="SEA",IF(AP2="","On Hold","Released"),"")
A3: PO00000050458HFPEARANCONVPE691300300 | B3: 20 | C3: 46154 | D3: 22 | E3: LATAM | F3: BAR | G3: PE | H3: HFPE | I3: TRK | J3: ARAN | K3: CONV | L3: PO00000050458 | M3: PE691300300 | N3: BERRYGOOD COM. IMP. E DISTRIBUICAO | O3: BERRYGOOD | P3: TERRESTRE | R3: 46167 | S3: 46167 | T3: MILTEX | U3: =+IF(Bitacora_2[[#This Row],[ATA DOC]]<>"",Bitacora_2[[#This Row],[ATA DOC]], IF(Bitacora_2[[#This Row],[Clase Expedición]]="AIR",Bitacora_2[[#This Row],[ETD Real]], IF(AND(Bitacora_2[[#This Row],[Clase Expedición]]="SEA",Bitacora_2[[#This Row],[Mercado]]="LATAM"), Bitacora_2[[#This Row],[ETD Real]]+3, IF(AND(Bitacora_2[[#This Row],[Clase Expedición]]="SEA",Bitacora_2[[#This Row],[Mercado]]="EUROPE"), Bitacora_2[[#This Row],[ETD Real]]+8, IF(AND(Bitacora_2[[#This Row],[Clase Expedición]]="SEA",Bitacora_2[[#This Row],[Mercado]]="UK"), Bitacora_2[[#This Row],[ETD Real]]+11, IF(AND(Bitacora_2[[#This Row],[Clase Expedición]]="SEA",OR(Bitacora_2[[#This Row],[Mercado]]="ASIA",Bitacora_2[[#This Row],[Mercado]]="ASIA CN + HK")), Bitacora_2[[#This Row],[ETD Real]]+14, IF(AND(Bitacora_2[[#This Row],[Clase Expedición]]="SEA",OR(Bitacora_2[[#This Row],[Mercado]]="US EAST",Bitacora_2[[#This Row],[Mercado]]="US WEST",Bitacora_2[[#This Row],[Mercado]]="US SOUTH")), Bitacora_2[[#This Row],[ETD Real]]+8,""))))))) | X3: =IF(OR(Bitacora_2[[#This Row],[ETD Real]]="",Bitacora_2[[#This Row],[ETD Doc]]=""),"",Bitacora_2[[#This Row],[ETD Doc]]-Bitacora_2[[#This Row],[ETD Real]]) | Y3: =IF(OR(Bitacora_2[[#This Row],[ATA DOC]]="",Bitacora_2[[#This Row],[ETA Real]]=""),"",Bitacora_2[[#This Row],[ETA Real]]-Bitacora_2[[#This Row],[ATA DOC]]) | AI3: =IF(AND(OR(E3="US EAST",E3="US WEST",E3="US SOUTH"),I3="SEA",Bitacora_2[[#This Row],[ETD Real]]-TODAY()>=3,Bitacora_2[[#This Row],[ISF]]<>"X"),"Pending", IF(AND(OR(E3="US EAST",E3="US WEST",E3="US SOUTH"),I3="SEA",Bitacora_2[[#This Row],[ETD Real]]-TODAY()=2,Bitacora_2[[#This Row],[ISF]]<>"X"),"Urgente", IF(AND(OR(E3="US EAST",E3="US WEST",E3="US SOUTH"),I3="SEA",Bitacora_2[[#This Row],[ETD Real]]-TODAY()<=1,Bitacora_2[[#This Row],[ISF]]<>"X"),"Muy Urgente", IF(AND(OR(E3="US EAST",E3="US WEST",E3="US SOUTH"),I3="SEA",Bitacora_2[[#This Row],[ISF]]="X"),"Sent","")))) | AJ3: =IF(AND(OR(Bitacora_2[[#This Row],[Clase Expedición]]="AIR",Bitacora_2[[#This Row],[Clase Expedición]]="TRK")),"Complete", IF(AND(Bitacora_2[[#This Row],[Mercado]]="LATAM",COUNTA(Bitacora_2[[#This Row],[PHYTO]:[ISF]],Bitacora_2[[#This Row],[CO]])=7,Bitacora_2[[#This Row],[Clase Expedición]]<>"TRK"), "Complete", IF(AND(Bitacora_2[[#This Row],[Mercado]]="LATAM",COUNTA(Bitacora_2[[#This Row],[PHYTO]:[PL ]],Bitacora_2[[#This Row],[CO]])=6,Bitacora_2[[#This Row],[Clase Expedición]]="SEA"), "Complete", IF(AND(OR(Bitacora_2[[#This Row],[Mercado]]="EUROPE",Bitacora_2[[#This Row],[Mercado]]="UK"),COUNTA(Bitacora_2[[#This Row],[PHYTO]],Bitacora_2[[#This Row],[INVOICE]:[PL ]],Bitacora_2[[#This Row],[COI]])=5,Bitacora_2[[#This Row],[Clase Expedición]]="SEA",Bitacora_2[[#This Row],[Manejo]]="ORG"), "Complete", IF(AND(OR(Bitacora_2[[#This Row],[Mercado]]="EUROPE",Bitacora_2[[#This Row],[Mercado]]="UK"),COUNTA(Bitacora_2[[#This Row],[PHYTO]],Bitacora_2[[#This Row],[INVOICE]:[PL ]])=4,Bitacora_2[[#This Row],[Clase Expedición]]="SEA",Bitacora_2[[#This Row],[Manejo]]="CONV"), "Complete", IF(AND(OR(Bitacora_2[[#This Row],[Mercado]]="US WEST",Bitacora_2[[#This Row],[Mercado]]="US EAST",Bitacora_2[[#This Row],[Mercado]]="US SOUTH"),COUNTA(Bitacora_2[[#This Row],[PHYTO]:[ISF]],Bitacora_2[[#This Row],[CO]])=7,Bitacora_2[[#This Row],[Clase Expedición]]="SEA",Bitacora_2[[#This Row],[Exportador]]="ECHF"), "Complete", IF(AND(OR(Bitacora_2[[#This Row],[Mercado]]="US WEST",Bitacora_2[[#This Row],[Mercado]]="US EAST",Bitacora_2[[#This Row],[Mercado]]="US SOUTH"),COUNTA(Bitacora_2[[#This Row],[PHYTO]:[ISF]])=6,Bitacora_2[[#This Row],[Clase Expedición]]="SEA",Bitacora_2[[#This Row],[Exportador]]<>"ECHF"), "Complete", IF(AND(OR(Bitacora_2[[#This Row],[Mercado]]="ASIA",Bitacora_2[[#This Row],[Mercado]]="ASIA CN + HK"),COUNTA(Bitacora_2[[#This Row],[PHYTO]:[PL ]],Bitacora_2[[#This Row],[CO]])=6), "Complete","Incomplete")))))))) -> Complete | AM3: =+IF(OR(Bitacora_2[[#This Row],[Exportador]]="INVERSIONES JORDIE",Bitacora_2[[#This Row],[Exportador]]="TAL S.A."), "Tercero", "Propio") -> Propio | AN3: =IF(AND(Bitacora_2[[#This Row],[Clase Expedición]]="AIR",OR(Bitacora_2[[#This Row],[Mercado]]="US EAST",Bitacora_2[[#This Row],[Mercado]]="US WEST",Bitacora_2[[#This Row],[Mercado]]="US SOUTH")),IF(Bitacora_2[[#This Row],[ETD Doc]]<>"","Delivered","Pending"), IF(Bitacora_2[[#This Row],[Clase Expedición]]="AIR","Delivered", IF(AND(Bitacora_2[[#This Row],[ETD Doc]]="",Bitacora_2[[#This Row],[ATA DOC]]=""),"Pending", IF(AND(Bitacora_2[[#This Row],[ETD Doc]]<>"",Bitacora_2[[#This Row],[ATA DOC]]=""),"In transit", IF(AND(Bitacora_2[[#This Row],[ETD Doc]]<>"",Bitacora_2[[#This Row],[ATA DOC]]<>""),"Delivered",""))))) -> Pending | AQ3: =IF(I3="SEA",IF(AP3="","On Hold","Released"),"")
A4: PO00000050664HFPEARANCONV145-12060720 | B4: 20 | C4: 46158 | D4: 21 | E4: LATAM | F4: BOG | G4: PE | H4: HFPE | I4: AIR | J4: ARAN | K4: CONV | L4: PO00000050664 | M4: 145-12060720 | N4: HORTIFRUT COLOMBIA SAS | O4: HORTIFRUT COLOMBIA | P4: LATAM | Q4: 24 | R4: 46161 | S4: 46161 | T4: HELLMANN | U4: =+IF(Bitacora_2[[#This Row],[ATA DOC]]<>"",Bitacora_2[[#This Row],[ATA DOC]], IF(Bitacora_2[[#This Row],[Clase Expedición]]="AIR",Bitacora_2[[#This Row],[ETD Real]], IF(AND(Bitacora_2[[#This Row],[Clase Expedición]]="SEA",Bitacora_2[[#This Row],[Mercado]]="LATAM"), Bitacora_2[[#This Row],[ETD Real]]+3, IF(AND(Bitacora_2[[#This Row],[Clase Expedición]]="SEA",Bitacora_2[[#This Row],[Mercado]]="EUROPE"), Bitacora_2[[#This Row],[ETD Real]]+8, IF(AND(Bitacora_2[[#This Row],[Clase Expedición]]="SEA",Bitacora_2[[#This Row],[Mercado]]="UK"), Bitacora_2[[#This Row],[ETD Real]]+11, IF(AND(Bitacora_2[[#This Row],[Clase Expedición]]="SEA",OR(Bitacora_2[[#This Row],[Mercado]]="ASIA",Bitacora_2[[#This Row],[Mercado]]="ASIA CN + HK")), Bitacora_2[[#This Row],[ETD Real]]+14, IF(AND(Bitacora_2[[#This Row],[Clase Expedición]]="SEA",OR(Bitacora_2[[#This Row],[Mercado]]="US EAST",Bitacora_2[[#This Row],[Mercado]]="US WEST",Bitacora_2[[#This Row],[Mercado]]="US SOUTH")), Bitacora_2[[#This Row],[ETD Real]]+8,""))))))) -> 46161 | X4: =IF(OR(Bitacora_2[[#This Row],[ETD Real]]="",Bitacora_2[[#This Row],[ETD Doc]]=""),"",Bitacora_2[[#This Row],[ETD Doc]]-Bitacora_2[[#This Row],[ETD Real]]) | Y4: =IF(OR(Bitacora_2[[#This Row],[ATA DOC]]="",Bitacora_2[[#This Row],[ETA Real]]=""),"",Bitacora_2[[#This Row],[ETA Real]]-Bitacora_2[[#This Row],[ATA DOC]]) | AI4: =IF(AND(OR(E4="US EAST",E4="US WEST",E4="US SOUTH"),I4="SEA",Bitacora_2[[#This Row],[ETD Real]]-TODAY()>=3,Bitacora_2[[#This Row],[ISF]]<>"X"),"Pending", IF(AND(OR(E4="US EAST",E4="US WEST",E4="US SOUTH"),I4="SEA",Bitacora_2[[#This Row],[ETD Real]]-TODAY()=2,Bitacora_2[[#This Row],[ISF]]<>"X"),"Urgente", IF(AND(OR(E4="US EAST",E4="US WEST",E4="US SOUTH"),I4="SEA",Bitacora_2[[#This Row],[ETD Real]]-TODAY()<=1,Bitacora_2[[#This Row],[ISF]]<>"X"),"Muy Urgente", IF(AND(OR(E4="US EAST",E4="US WEST",E4="US SOUTH"),I4="SEA",Bitacora_2[[#This Row],[ISF]]="X"),"Sent","")))) | AJ4: =IF(AND(OR(Bitacora_2[[#This Row],[Clase Expedición]]="AIR",Bitacora_2[[#This Row],[Clase Expedición]]="TRK")),"Complete", IF(AND(Bitacora_2[[#This Row],[Mercado]]="LATAM",COUNTA(Bitacora_2[[#This Row],[PHYTO]:[ISF]],Bitacora_2[[#This Row],[CO]])=7,Bitacora_2[[#This Row],[Clase Expedición]]<>"TRK"), "Complete", IF(AND(Bitacora_2[[#This Row],[Mercado]]="LATAM",COUNTA(Bitacora_2[[#This Row],[PHYTO]:[PL ]],Bitacora_2[[#This Row],[CO]])=6,Bitacora_2[[#This Row],[Clase Expedición]]="SEA"), "Complete", IF(AND(OR(Bitacora_2[[#This Row],[Mercado]]="EUROPE",Bitacora_2[[#This Row],[Mercado]]="UK"),COUNTA(Bitacora_2[[#This Row],[PHYTO]],Bitacora_2[[#This Row],[INVOICE]:[PL ]],Bitacora_2[[#This Row],[COI]])=5,Bitacora_2[[#This Row],[Clase Expedición]]="SEA",Bitacora_2[[#This Row],[Manejo]]="ORG"), "Complete", IF(AND(OR(Bitacora_2[[#This Row],[Mercado]]="EUROPE",Bitacora_2[[#This Row],[Mercado]]="UK"),COUNTA(Bitacora_2[[#This Row],[PHYTO]],Bitacora_2[[#This Row],[INVOICE]:[PL ]])=4,Bitacora_2[[#This Row],[Clase Expedición]]="SEA",Bitacora_2[[#This Row],[Manejo]]="CONV"), "Complete", IF(AND(OR(Bitacora_2[[#This Row],[Mercado]]="US WEST",Bitacora_2[[#This Row],[Mercado]]="US EAST",Bitacora_2[[#This Row],[Mercado]]="US SOUTH"),COUNTA(Bitacora_2[[#This Row],[PHYTO]:[ISF]],Bitacora_2[[#This Row],[CO]])=7,Bitacora_2[[#This Row],[Clase Expedición]]="SEA",Bitacora_2[[#This Row],[Exportador]]="ECHF"), "Complete", IF(AND(OR(Bitacora_2[[#This Row],[Mercado]]="US WEST",Bitacora_2[[#This Row],[Mercado]]="US EAST",Bitacora_2[[#This Row],[Mercado]]="US SOUTH"),COUNTA(Bitacora_2[[#This Row],[PHYTO]:[ISF]])=6,Bitacora_2[[#This Row],[Clase Expedición]]="SEA",Bitacora_2[[#This Row],[Exportador]]<>"ECHF"), "Complete", IF(AND(OR(Bitacora_2[[#This Row],[Mercado]]="ASIA",Bitacora_2[[#This Row],[Mercado]]="ASIA CN + HK"),COUNTA(Bitacora_2[[#This Row],[PHYTO]:[PL ]],Bitacora_2[[#This Row],[CO]])=6), "Complete","Incomplete")))))))) -> Complete | AM4: =+IF(OR(Bitacora_2[[#This Row],[Exportador]]="INVERSIONES JORDIE",Bitacora_2[[#This Row],[Exportador]]="TAL S.A."), "Tercero", "Propio") -> Propio | AN4: =IF(AND(Bitacora_2[[#This Row],[Clase Expedición]]="AIR",OR(Bitacora_2[[#This Row],[Mercado]]="US EAST",Bitacora_2[[#This Row],[Mercado]]="US WEST",Bitacora_2[[#This Row],[Mercado]]="US SOUTH")),IF(Bitacora_2[[#This Row],[ETD Doc]]<>"","Delivered","Pending"), IF(Bitacora_2[[#This Row],[Clase Expedición]]="AIR","Delivered", IF(AND(Bitacora_2[[#This Row],[ETD Doc]]="",Bitacora_2[[#This Row],[ATA DOC]]=""),"Pending", IF(AND(Bitacora_2[[#This Row],[ETD Doc]]<>"",Bitacora_2[[#This Row],[ATA DOC]]=""),"In transit", IF(AND(Bitacora_2[[#This Row],[ETD Doc]]<>"",Bitacora_2[[#This Row],[ATA DOC]]<>""),"Delivered",""))))) -> Delivered | AQ4: =IF(I4="SEA",IF(AP4="","On Hold","Released"),"")
A5: PO00000050665HFPEARANCONV145-12060926 | B5: 20 | C5: 46158 | D5: 21 | E5: LATAM | F5: GRU | G5: PE | H5: HFPE | I5: AIR | J5: ARAN | K5: CONV | L5: PO00000050665 | M5: 145-12060926 | N5: BERRYGOOD COM. IMP. E DISTRIBUICAO | O5: BERRYGOOD | P5: LATAM | Q5: 24 | R5: 46162 | S5: 46162 | T5: HELLMANN | U5: =+IF(Bitacora_2[[#This Row],[ATA DOC]]<>"",Bitacora_2[[#This Row],[ATA DOC]], IF(Bitacora_2[[#This Row],[Clase Expedición]]="AIR",Bitacora_2[[#This Row],[ETD Real]], IF(AND(Bitacora_2[[#This Row],[Clase Expedición]]="SEA",Bitacora_2[[#This Row],[Mercado]]="LATAM"), Bitacora_2[[#This Row],[ETD Real]]+3, IF(AND(Bitacora_2[[#This Row],[Clase Expedición]]="SEA",Bitacora_2[[#This Row],[Mercado]]="EUROPE"), Bitacora_2[[#This Row],[ETD Real]]+8, IF(AND(Bitacora_2[[#This Row],[Clase Expedición]]="SEA",Bitacora_2[[#This Row],[Mercado]]="UK"), Bitacora_2[[#This Row],[ETD Real]]+11, IF(AND(Bitacora_2[[#This Row],[Clase Expedición]]="SEA",OR(Bitacora_2[[#This Row],[Mercado]]="ASIA",Bitacora_2[[#This Row],[Mercado]]="ASIA CN + HK")), Bitacora_2[[#This Row],[ETD Real]]+14, IF(AND(Bitacora_2[[#This Row],[Clase Expedición]]="SEA",OR(Bitacora_2[[#This Row],[Mercado]]="US EAST",Bitacora_2[[#This Row],[Mercado]]="US WEST",Bitacora_2[[#This Row],[Mercado]]="US SOUTH")), Bitacora_2[[#This Row],[ETD Real]]+8,""))))))) -> 46162 | X5: =IF(OR(Bitacora_2[[#This Row],[ETD Real]]="",Bitacora_2[[#This Row],[ETD Doc]]=""),"",Bitacora_2[[#This Row],[ETD Doc]]-Bitacora_2[[#This Row],[ETD Real]]) | Y5: =IF(OR(Bitacora_2[[#This Row],[ATA DOC]]="",Bitacora_2[[#This Row],[ETA Real]]=""),"",Bitacora_2[[#This Row],[ETA Real]]-Bitacora_2[[#This Row],[ATA DOC]]) | AI5: =IF(AND(OR(E5="US EAST",E5="US WEST",E5="US SOUTH"),I5="SEA",Bitacora_2[[#This Row],[ETD Real]]-TODAY()>=3,Bitacora_2[[#This Row],[ISF]]<>"X"),"Pending", IF(AND(OR(E5="US EAST",E5="US WEST",E5="US SOUTH"),I5="SEA",Bitacora_2[[#This Row],[ETD Real]]-TODAY()=2,Bitacora_2[[#This Row],[ISF]]<>"X"),"Urgente", IF(AND(OR(E5="US EAST",E5="US WEST",E5="US SOUTH"),I5="SEA",Bitacora_2[[#This Row],[ETD Real]]-TODAY()<=1,Bitacora_2[[#This Row],[ISF]]<>"X"),"Muy Urgente", IF(AND(OR(E5="US EAST",E5="US WEST",E5="US SOUTH"),I5="SEA",Bitacora_2[[#This Row],[ISF]]="X"),"Sent","")))) | AJ5: =IF(AND(OR(Bitacora_2[[#This Row],[Clase Expedición]]="AIR",Bitacora_2[[#This Row],[Clase Expedición]]="TRK")),"Complete", IF(AND(Bitacora_2[[#This Row],[Mercado]]="LATAM",COUNTA(Bitacora_2[[#This Row],[PHYTO]:[ISF]],Bitacora_2[[#This Row],[CO]])=7,Bitacora_2[[#This Row],[Clase Expedición]]<>"TRK"), "Complete", IF(AND(Bitacora_2[[#This Row],[Mercado]]="LATAM",COUNTA(Bitacora_2[[#This Row],[PHYTO]:[PL ]],Bitacora_2[[#This Row],[CO]])=6,Bitacora_2[[#This Row],[Clase Expedición]]="SEA"), "Complete", IF(AND(OR(Bitacora_2[[#This Row],[Mercado]]="EUROPE",Bitacora_2[[#This Row],[Mercado]]="UK"),COUNTA(Bitacora_2[[#This Row],[PHYTO]],Bitacora_2[[#This Row],[INVOICE]:[PL ]],Bitacora_2[[#This Row],[COI]])=5,Bitacora_2[[#This Row],[Clase Expedición]]="SEA",Bitacora_2[[#This Row],[Manejo]]="ORG"), "Complete", IF(AND(OR(Bitacora_2[[#This Row],[Mercado]]="EUROPE",Bitacora_2[[#This Row],[Mercado]]="UK"),COUNTA(Bitacora_2[[#This Row],[PHYTO]],Bitacora_2[[#This Row],[INVOICE]:[PL ]])=4,Bitacora_2[[#This Row],[Clase Expedición]]="SEA",Bitacora_2[[#This Row],[Manejo]]="CONV"), "Complete", IF(AND(OR(Bitacora_2[[#This Row],[Mercado]]="US WEST",Bitacora_2[[#This Row],[Mercado]]="US EAST",Bitacora_2[[#This Row],[Mercado]]="US SOUTH"),COUNTA(Bitacora_2[[#This Row],[PHYTO]:[ISF]],Bitacora_2[[#This Row],[CO]])=7,Bitacora_2[[#This Row],[Clase Expedición]]="SEA",Bitacora_2[[#This Row],[Exportador]]="ECHF"), "Complete", IF(AND(OR(Bitacora_2[[#This Row],[Mercado]]="US WEST",Bitacora_2[[#This Row],[Mercado]]="US EAST",Bitacora_2[[#This Row],[Mercado]]="US SOUTH"),COUNTA(Bitacora_2[[#This Row],[PHYTO]:[ISF]])=6,Bitacora_2[[#This Row],[Clase Expedición]]="SEA",Bitacora_2[[#This Row],[Exportador]]<>"ECHF"), "Complete", IF(AND(OR(Bitacora_2[[#This Row],[Mercado]]="ASIA",Bitacora_2[[#This Row],[Mercado]]="ASIA CN + HK"),COUNTA(Bitacora_2[[#This Row],[PHYTO]:[PL ]],Bitacora_2[[#This Row],[CO]])=6), "Complete","Incomplete")))))))) -> Complete | AM5: =+IF(OR(Bitacora_2[[#This Row],[Exportador]]="INVERSIONES JORDIE",Bitacora_2[[#This Row],[Exportador]]="TAL S.A."), "Tercero", "Propio") -> Propio | AN5: =IF(AND(Bitacora_2[[#This Row],[Clase Expedición]]="AIR",OR(Bitacora_2[[#This Row],[Mercado]]="US EAST",Bitacora_2[[#This Row],[Mercado]]="US WEST",Bitacora_2[[#This Row],[Mercado]]="US SOUTH")),IF(Bitacora_2[[#This Row],[ETD Doc]]<>"","Delivered","Pending"), IF(Bitacora_2[[#This Row],[Clase Expedición]]="AIR","Delivered", IF(AND(Bitacora_2[[#This Row],[ETD Doc]]="",Bitacora_2[[#This Row],[ATA DOC]]=""),"Pending", IF(AND(Bitacora_2[[#This Row],[ETD Doc]]<>"",Bitacora_2[[#This Row],[ATA DOC]]=""),"In transit", IF(AND(Bitacora_2[[#This Row],[ETD Doc]]<>"",Bitacora_2[[#This Row],[ATA DOC]]<>""),"Delivered",""))))) -> Delivered | AQ5: =IF(I5="SEA",IF(AP5="","On Hold","Released"),"")
A6: PO00000050778HFPEARANCONV145-12061221 | B6: 21 | C6: 46164 | D6: 22 | E6: LATAM | F6: BOG | G6: PE | H6: HFPE | I6: AIR | J6: ARAN | K6: CONV | L6: PO00000050778 | M6: 145-12061221 | N6: HORTIFRUT COLOMBIA SAS | O6: HORTIFRUT COLOMBIA | P6: LATAM | Q6: 24 | R6: 46168 | S6: 46168 | T6: HELLMANN | U6: =+IF(Bitacora_2[[#This Row],[ATA DOC]]<>"",Bitacora_2[[#This Row],[ATA DOC]], IF(Bitacora_2[[#This Row],[Clase Expedición]]="AIR",Bitacora_2[[#This Row],[ETD Real]], IF(AND(Bitacora_2[[#This Row],[Clase Expedición]]="SEA",Bitacora_2[[#This Row],[Mercado]]="LATAM"), Bitacora_2[[#This Row],[ETD Real]]+3, IF(AND(Bitacora_2[[#This Row],[Clase Expedición]]="SEA",Bitacora_2[[#This Row],[Mercado]]="EUROPE"), Bitacora_2[[#This Row],[ETD Real]]+8, IF(AND(Bitacora_2[[#This Row],[Clase Expedición]]="SEA",Bitacora_2[[#This Row],[Mercado]]="UK"), Bitacora_2[[#This Row],[ETD Real]]+11, IF(AND(Bitacora_2[[#This Row],[Clase Expedición]]="SEA",OR(Bitacora_2[[#This Row],[Mercado]]="ASIA",Bitacora_2[[#This Row],[Mercado]]="ASIA CN + HK")), Bitacora_2[[#This Row],[ETD Real]]+14, IF(AND(Bitacora_2[[#This Row],[Clase Expedición]]="SEA",OR(Bitacora_2[[#This Row],[Mercado]]="US EAST",Bitacora_2[[#This Row],[Mercado]]="US WEST",Bitacora_2[[#This Row],[Mercado]]="US SOUTH")), Bitacora_2[[#This Row],[ETD Real]]+8,""))))))) -> 46168 | X6: =IF(OR(Bitacora_2[[#This Row],[ETD Real]]="",Bitacora_2[[#This Row],[ETD Doc]]=""),"",Bitacora_2[[#This Row],[ETD Doc]]-Bitacora_2[[#This Row],[ETD Real]]) | Y6: =IF(OR(Bitacora_2[[#This Row],[ATA DOC]]="",Bitacora_2[[#This Row],[ETA Real]]=""),"",Bitacora_2[[#This Row],[ETA Real]]-Bitacora_2[[#This Row],[ATA DOC]]) | AI6: =IF(AND(OR(E6="US EAST",E6="US WEST",E6="US SOUTH"),I6="SEA",Bitacora_2[[#This Row],[ETD Real]]-TODAY()>=3,Bitacora_2[[#This Row],[ISF]]<>"X"),"Pending", IF(AND(OR(E6="US EAST",E6="US WEST",E6="US SOUTH"),I6="SEA",Bitacora_2[[#This Row],[ETD Real]]-TODAY()=2,Bitacora_2[[#This Row],[ISF]]<>"X"),"Urgente", IF(AND(OR(E6="US EAST",E6="US WEST",E6="US SOUTH"),I6="SEA",Bitacora_2[[#This Row],[ETD Real]]-TODAY()<=1,Bitacora_2[[#This Row],[ISF]]<>"X"),"Muy Urgente", IF(AND(OR(E6="US EAST",E6="US WEST",E6="US SOUTH"),I6="SEA",Bitacora_2[[#This Row],[ISF]]="X"),"Sent","")))) | AJ6: =IF(AND(OR(Bitacora_2[[#This Row],[Clase Expedición]]="AIR",Bitacora_2[[#This Row],[Clase Expedición]]="TRK")),"Complete", IF(AND(Bitacora_2[[#This Row],[Mercado]]="LATAM",COUNTA(Bitacora_2[[#This Row],[PHYTO]:[ISF]],Bitacora_2[[#This Row],[CO]])=7,Bitacora_2[[#This Row],[Clase Expedición]]<>"TRK"), "Complete", IF(AND(Bitacora_2[[#This Row],[Mercado]]="LATAM",COUNTA(Bitacora_2[[#This Row],[PHYTO]:[PL ]],Bitacora_2[[#This Row],[CO]])=6,Bitacora_2[[#This Row],[Clase Expedición]]="SEA"), "Complete", IF(AND(OR(Bitacora_2[[#This Row],[Mercado]]="EUROPE",Bitacora_2[[#This Row],[Mercado]]="UK"),COUNTA(Bitacora_2[[#This Row],[PHYTO]],Bitacora_2[[#This Row],[INVOICE]:[PL ]],Bitacora_2[[#This Row],[COI]])=5,Bitacora_2[[#This Row],[Clase Expedición]]="SEA",Bitacora_2[[#This Row],[Manejo]]="ORG"), "Complete", IF(AND(OR(Bitacora_2[[#This Row],[Mercado]]="EUROPE",Bitacora_2[[#This Row],[Mercado]]="UK"),COUNTA(Bitacora_2[[#This Row],[PHYTO]],Bitacora_2[[#This Row],[INVOICE]:[PL ]])=4,Bitacora_2[[#This Row],[Clase Expedición]]="SEA",Bitacora_2[[#This Row],[Manejo]]="CONV"), "Complete", IF(AND(OR(Bitacora_2[[#This Row],[Mercado]]="US WEST",Bitacora_2[[#This Row],[Mercado]]="US EAST",Bitacora_2[[#This Row],[Mercado]]="US SOUTH"),COUNTA(Bitacora_2[[#This Row],[PHYTO]:[ISF]],Bitacora_2[[#This Row],[CO]])=7,Bitacora_2[[#This Row],[Clase Expedición]]="SEA",Bitacora_2[[#This Row],[Exportador]]="ECHF"), "Complete", IF(AND(OR(Bitacora_2[[#This Row],[Mercado]]="US WEST",Bitacora_2[[#This Row],[Mercado]]="US EAST",Bitacora_2[[#This Row],[Mercado]]="US SOUTH"),COUNTA(Bitacora_2[[#This Row],[PHYTO]:[ISF]])=6,Bitacora_2[[#This Row],[Clase Expedición]]="SEA",Bitacora_2[[#This Row],[Exportador]]<>"ECHF"), "Complete", IF(AND(OR(Bitacora_2[[#This Row],[Mercado]]="ASIA",Bitacora_2[[#This Row],[Mercado]]="ASIA CN + HK"),COUNTA(Bitacora_2[[#This Row],[PHYTO]:[PL ]],Bitacora_2[[#This Row],[CO]])=6), "Complete","Incomplete")))))))) -> Complete | AM6: =+IF(OR(Bitacora_2[[#This Row],[Exportador]]="INVERSIONES JORDIE",Bitacora_2[[#This Row],[Exportador]]="TAL S.A."), "Tercero", "Propio") -> Propio | AN6: =IF(AND(Bitacora_2[[#This Row],[Clase Expedición]]="AIR",OR(Bitacora_2[[#This Row],[Mercado]]="US EAST",Bitacora_2[[#This Row],[Mercado]]="US WEST",Bitacora_2[[#This Row],[Mercado]]="US SOUTH")),IF(Bitacora_2[[#This Row],[ETD Doc]]<>"","Delivered","Pending"), IF(Bitacora_2[[#This Row],[Clase Expedición]]="AIR","Delivered", IF(AND(Bitacora_2[[#This Row],[ETD Doc]]="",Bitacora_2[[#This Row],[ATA DOC]]=""),"Pending", IF(AND(Bitacora_2[[#This Row],[ETD Doc]]<>"",Bitacora_2[[#This Row],[ATA DOC]]=""),"In transit", IF(AND(Bitacora_2[[#This Row],[ETD Doc]]<>"",Bitacora_2[[#This Row],[ATA DOC]]<>""),"Delivered",""))))) -> Delivered | AQ6: =IF(I6="SEA",IF(AP6="","On Hold","Released"),"")
A7: PO00000050779HFPEARANCONV145-12061232 | B7: 21 | C7: 46164 | D7: 22 | E7: LATAM | F7: BOG | G7: PE | H7: HFPE | I7: AIR | J7: ARAN | K7: CONV | L7: PO00000050779 | M7: 145-12061232 | N7: HORTIFRUT COLOMBIA SAS | O7: HORTIFRUT COLOMBIA | P7: LATAM | Q7: 24 | R7: 46168 | S7: 46168 | T7: HELLMANN | U7: =+IF(Bitacora_2[[#This Row],[ATA DOC]]<>"",Bitacora_2[[#This Row],[ATA DOC]], IF(Bitacora_2[[#This Row],[Clase Expedición]]="AIR",Bitacora_2[[#This Row],[ETD Real]], IF(AND(Bitacora_2[[#This Row],[Clase Expedición]]="SEA",Bitacora_2[[#This Row],[Mercado]]="LATAM"), Bitacora_2[[#This Row],[ETD Real]]+3, IF(AND(Bitacora_2[[#This Row],[Clase Expedición]]="SEA",Bitacora_2[[#This Row],[Mercado]]="EUROPE"), Bitacora_2[[#This Row],[ETD Real]]+8, IF(AND(Bitacora_2[[#This Row],[Clase Expedición]]="SEA",Bitacora_2[[#This Row],[Mercado]]="UK"), Bitacora_2[[#This Row],[ETD Real]]+11, IF(AND(Bitacora_2[[#This Row],[Clase Expedición]]="SEA",OR(Bitacora_2[[#This Row],[Mercado]]="ASIA",Bitacora_2[[#This Row],[Mercado]]="ASIA CN + HK")), Bitacora_2[[#This Row],[ETD Real]]+14, IF(AND(Bitacora_2[[#This Row],[Clase Expedición]]="SEA",OR(Bitacora_2[[#This Row],[Mercado]]="US EAST",Bitacora_2[[#This Row],[Mercado]]="US WEST",Bitacora_2[[#This Row],[Mercado]]="US SOUTH")), Bitacora_2[[#This Row],[ETD Real]]+8,""))))))) -> 46168 | X7: =IF(OR(Bitacora_2[[#This Row],[ETD Real]]="",Bitacora_2[[#This Row],[ETD Doc]]=""),"",Bitacora_2[[#This Row],[ETD Doc]]-Bitacora_2[[#This Row],[ETD Real]]) | Y7: =IF(OR(Bitacora_2[[#This Row],[ATA DOC]]="",Bitacora_2[[#This Row],[ETA Real]]=""),"",Bitacora_2[[#This Row],[ETA Real]]-Bitacora_2[[#This Row],[ATA DOC]]) | AI7: =IF(AND(OR(E7="US EAST",E7="US WEST",E7="US SOUTH"),I7="SEA",Bitacora_2[[#This Row],[ETD Real]]-TODAY()>=3,Bitacora_2[[#This Row],[ISF]]<>"X"),"Pending", IF(AND(OR(E7="US EAST",E7="US WEST",E7="US SOUTH"),I7="SEA",Bitacora_2[[#This Row],[ETD Real]]-TODAY()=2,Bitacora_2[[#This Row],[ISF]]<>"X"),"Urgente", IF(AND(OR(E7="US EAST",E7="US WEST",E7="US SOUTH"),I7="SEA",Bitacora_2[[#This Row],[ETD Real]]-TODAY()<=1,Bitacora_2[[#This Row],[ISF]]<>"X"),"Muy Urgente", IF(AND(OR(E7="US EAST",E7="US WEST",E7="US SOUTH"),I7="SEA",Bitacora_2[[#This Row],[ISF]]="X"),"Sent","")))) | AJ7: =IF(AND(OR(Bitacora_2[[#This Row],[Clase Expedición]]="AIR",Bitacora_2[[#This Row],[Clase Expedición]]="TRK")),"Complete", IF(AND(Bitacora_2[[#This Row],[Mercado]]="LATAM",COUNTA(Bitacora_2[[#This Row],[PHYTO]:[ISF]],Bitacora_2[[#This Row],[CO]])=7,Bitacora_2[[#This Row],[Clase Expedición]]<>"TRK"), "Complete", IF(AND(Bitacora_2[[#This Row],[Mercado]]="LATAM",COUNTA(Bitacora_2[[#This Row],[PHYTO]:[PL ]],Bitacora_2[[#This Row],[CO]])=6,Bitacora_2[[#This Row],[Clase Expedición]]="SEA"), "Complete", IF(AND(OR(Bitacora_2[[#This Row],[Mercado]]="EUROPE",Bitacora_2[[#This Row],[Mercado]]="UK"),COUNTA(Bitacora_2[[#This Row],[PHYTO]],Bitacora_2[[#This Row],[INVOICE]:[PL ]],Bitacora_2[[#This Row],[COI]])=5,Bitacora_2[[#This Row],[Clase Expedición]]="SEA",Bitacora_2[[#This Row],[Manejo]]="ORG"), "Complete", IF(AND(OR(Bitacora_2[[#This Row],[Mercado]]="EUROPE",Bitacora_2[[#This Row],[Mercado]]="UK"),COUNTA(Bitacora_2[[#This Row],[PHYTO]],Bitacora_2[[#This Row],[INVOICE]:[PL ]])=4,Bitacora_2[[#This Row],[Clase Expedición]]="SEA",Bitacora_2[[#This Row],[Manejo]]="CONV"), "Complete", IF(AND(OR(Bitacora_2[[#This Row],[Mercado]]="US WEST",Bitacora_2[[#This Row],[Mercado]]="US EAST",Bitacora_2[[#This Row],[Mercado]]="US SOUTH"),COUNTA(Bitacora_2[[#This Row],[PHYTO]:[ISF]],Bitacora_2[[#This Row],[CO]])=7,Bitacora_2[[#This Row],[Clase Expedición]]="SEA",Bitacora_2[[#This Row],[Exportador]]="ECHF"), "Complete", IF(AND(OR(Bitacora_2[[#This Row],[Mercado]]="US WEST",Bitacora_2[[#This Row],[Mercado]]="US EAST",Bitacora_2[[#This Row],[Mercado]]="US SOUTH"),COUNTA(Bitacora_2[[#This Row],[PHYTO]:[ISF]])=6,Bitacora_2[[#This Row],[Clase Expedición]]="SEA",Bitacora_2[[#This Row],[Exportador]]<>"ECHF"), "Complete", IF(AND(OR(Bitacora_2[[#This Row],[Mercado]]="ASIA",Bitacora_2[[#This Row],[Mercado]]="ASIA CN + HK"),COUNTA(Bitacora_2[[#This Row],[PHYTO]:[PL ]],Bitacora_2[[#This Row],[CO]])=6), "Complete","Incomplete")))))))) -> Complete | AM7: =+IF(OR(Bitacora_2[[#This Row],[Exportador]]="INVERSIONES JORDIE",Bitacora_2[[#This Row],[Exportador]]="TAL S.A."), "Tercero", "Propio") -> Propio | AN7: =IF(AND(Bitacora_2[[#This Row],[Clase Expedición]]="AIR",OR(Bitacora_2[[#This Row],[Mercado]]="US EAST",Bitacora_2[[#This Row],[Mercado]]="US WEST",Bitacora_2[[#This Row],[Mercado]]="US SOUTH")),IF(Bitacora_2[[#This Row],[ETD Doc]]<>"","Delivered","Pending"), IF(Bitacora_2[[#This Row],[Clase Expedición]]="AIR","Delivered", IF(AND(Bitacora_2[[#This Row],[ETD Doc]]="",Bitacora_2[[#This Row],[ATA DOC]]=""),"Pending", IF(AND(Bitacora_2[[#This Row],[ETD Doc]]<>"",Bitacora_2[[#This Row],[ATA DOC]]=""),"In transit", IF(AND(Bitacora_2[[#This Row],[ETD Doc]]<>"",Bitacora_2[[#This Row],[ATA DOC]]<>""),"Delivered",""))))) -> Delivered | AQ7: =IF(I7="SEA",IF(AP7="","On Hold","Released"),"")
A8: RC-3547TTAL S.A.ARANCONV145-12061206 | B8: 21 | C8: 46165 | D8: 22 | E8: LATAM | F8: GRU | G8: PE | H8: TAL S.A. | I8: AIR | J8: ARAN | K8: CONV | L8: RC-3547T | M8: 145-12061206 | O8: BERRYGOOD | P8: LATAM | R8: 46167 | S8: 46167 | U8: =+IF(Bitacora_2[[#This Row],[ATA DOC]]<>"",Bitacora_2[[#This Row],[ATA DOC]], IF(Bitacora_2[[#This Row],[Clase Expedición]]="AIR",Bitacora_2[[#This Row],[ETD Real]], IF(AND(Bitacora_2[[#This Row],[Clase Expedición]]="SEA",Bitacora_2[[#This Row],[Mercado]]="LATAM"), Bitacora_2[[#This Row],[ETD Real]]+3, IF(AND(Bitacora_2[[#This Row],[Clase Expedición]]="SEA",Bitacora_2[[#This Row],[Mercado]]="EUROPE"), Bitacora_2[[#This Row],[ETD Real]]+8, IF(AND(Bitacora_2[[#This Row],[Clase Expedición]]="SEA",Bitacora_2[[#This Row],[Mercado]]="UK"), Bitacora_2[[#This Row],[ETD Real]]+11, IF(AND(Bitacora_2[[#This Row],[Clase Expedición]]="SEA",OR(Bitacora_2[[#This Row],[Mercado]]="ASIA",Bitacora_2[[#This Row],[Mercado]]="ASIA CN + HK")), Bitacora_2[[#This Row],[ETD Real]]+14, IF(AND(Bitacora_2[[#This Row],[Clase Expedición]]="SEA",OR(Bitacora_2[[#This Row],[Mercado]]="US EAST",Bitacora_2[[#This Row],[Mercado]]="US WEST",Bitacora_2[[#This Row],[Mercado]]="US SOUTH")), Bitacora_2[[#This Row],[ETD Real]]+8,""))))))) -> 46167 | X8: =IF(OR(Bitacora_2[[#This Row],[ETD Real]]="",Bitacora_2[[#This Row],[ETD Doc]]=""),"",Bitacora_2[[#This Row],[ETD Doc]]-Bitacora_2[[#This Row],[ETD Real]]) | Y8: =IF(OR(Bitacora_2[[#This Row],[ATA DOC]]="",Bitacora_2[[#This Row],[ETA Real]]=""),"",Bitacora_2[[#This Row],[ETA Real]]-Bitacora_2[[#This Row],[ATA DOC]]) | AI8: =IF(AND(OR(E8="US EAST",E8="US WEST",E8="US SOUTH"),I8="SEA",Bitacora_2[[#This Row],[ETD Real]]-TODAY()>=3,Bitacora_2[[#This Row],[ISF]]<>"X"),"Pending", IF(AND(OR(E8="US EAST",E8="US WEST",E8="US SOUTH"),I8="SEA",Bitacora_2[[#This Row],[ETD Real]]-TODAY()=2,Bitacora_2[[#This Row],[ISF]]<>"X"),"Urgente", IF(AND(OR(E8="US EAST",E8="US WEST",E8="US SOUTH"),I8="SEA",Bitacora_2[[#This Row],[ETD Real]]-TODAY()<=1,Bitacora_2[[#This Row],[ISF]]<>"X"),"Muy Urgente", IF(AND(OR(E8="US EAST",E8="US WEST",E8="US SOUTH"),I8="SEA",Bitacora_2[[#This Row],[ISF]]="X"),"Sent","")))) | AJ8: =IF(AND(OR(Bitacora_2[[#This Row],[Clase Expedición]]="AIR",Bitacora_2[[#This Row],[Clase Expedición]]="TRK")),"Complete", IF(AND(Bitacora_2[[#This Row],[Mercado]]="LATAM",COUNTA(Bitacora_2[[#This Row],[PHYTO]:[ISF]],Bitacora_2[[#This Row],[CO]])=7,Bitacora_2[[#This Row],[Clase Expedición]]<>"TRK"), "Complete", IF(AND(Bitacora_2[[#This Row],[Mercado]]="LATAM",COUNTA(Bitacora_2[[#This Row],[PHYTO]:[PL ]],Bitacora_2[[#This Row],[CO]])=6,Bitacora_2[[#This Row],[Clase Expedición]]="SEA"), "Complete", IF(AND(OR(Bitacora_2[[#This Row],[Mercado]]="EUROPE",Bitacora_2[[#This Row],[Mercado]]="UK"),COUNTA(Bitacora_2[[#This Row],[PHYTO]],Bitacora_2[[#This Row],[INVOICE]:[PL ]],Bitacora_2[[#This Row],[COI]])=5,Bitacora_2[[#This Row],[Clase Expedición]]="SEA",Bitacora_2[[#This Row],[Manejo]]="ORG"), "Complete", IF(AND(OR(Bitacora_2[[#This Row],[Mercado]]="EUROPE",Bitacora_2[[#This Row],[Mercado]]="UK"),COUNTA(Bitacora_2[[#This Row],[PHYTO]],Bitacora_2[[#This Row],[INVOICE]:[PL ]])=4,Bitacora_2[[#This Row],[Clase Expedición]]="SEA",Bitacora_2[[#This Row],[Manejo]]="CONV"), "Complete", IF(AND(OR(Bitacora_2[[#This Row],[Mercado]]="US WEST",Bitacora_2[[#This Row],[Mercado]]="US EAST",Bitacora_2[[#This Row],[Mercado]]="US SOUTH"),COUNTA(Bitacora_2[[#This Row],[PHYTO]:[ISF]],Bitacora_2[[#This Row],[CO]])=7,Bitacora_2[[#This Row],[Clase Expedición]]="SEA",Bitacora_2[[#This Row],[Exportador]]="ECHF"), "Complete", IF(AND(OR(Bitacora_2[[#This Row],[Mercado]]="US WEST",Bitacora_2[[#This Row],[Mercado]]="US EAST",Bitacora_2[[#This Row],[Mercado]]="US SOUTH"),COUNTA(Bitacora_2[[#This Row],[PHYTO]:[ISF]])=6,Bitacora_2[[#This Row],[Clase Expedición]]="SEA",Bitacora_2[[#This Row],[Exportador]]<>"ECHF"), "Complete", IF(AND(OR(Bitacora_2[[#This Row],[Mercado]]="ASIA",Bitacora_2[[#This Row],[Mercado]]="ASIA CN + HK"),COUNTA(Bitacora_2[[#This Row],[PHYTO]:[PL ]],Bitacora_2[[#This Row],[CO]])=6), "Complete","Incomplete")))))))) -> Complete | AM8: =+IF(OR(Bitacora_2[[#This Row],[Exportador]]="INVERSIONES JORDIE",Bitacora_2[[#This Row],[Exportador]]="TAL S.A."), "Tercero", "Propio") -> Tercero | AN8: =IF(AND(Bitacora_2[[#This Row],[Clase Expedición]]="AIR",OR(Bitacora_2[[#This Row],[Mercado]]="US EAST",Bitacora_2[[#This Row],[Mercado]]="US WEST",Bitacora_2[[#This Row],[Mercado]]="US SOUTH")),IF(Bitacora_2[[#This Row],[ETD Doc]]<>"","Delivered","Pending"), IF(Bitacora_2[[#This Row],[Clase Expedición]]="AIR","Delivered", IF(AND(Bitacora_2[[#This Row],[ETD Doc]]="",Bitacora_2[[#This Row],[ATA DOC]]=""),"Pending", IF(AND(Bitacora_2[[#This Row],[ETD Doc]]<>"",Bitacora_2[[#This Row],[ATA DOC]]=""),"In transit", IF(AND(Bitacora_2[[#This Row],[ETD Doc]]<>"",Bitacora_2[[#This Row],[ATA DOC]]<>""),"Delivered",""))))) -> Delivered | AQ8: =IF(I8="SEA",IF(AP8="","On Hold","Released"),"")
A9: PO00000050807HFPEARANCONVOERU4327243 | B9: 22 | C9: 46168 | D9: 26 | E9: LATAM | F9: CLSAI | G9: PE | H9: HFPE | I9: SEA | J9: ARAN | K9: CONV | L9: PO00000050807 | M9: OERU4327243 | N9: HORTIFRUT COMERCIAL S.A. | O9: HORTIFRUT CHILE | P9: COSCO | Q9: COSCO MALAYSIA 109W | R9: 46189 | S9: 46194 | T9: NWT | U9: =+IF(Bitacora_2[[#This Row],[ATA DOC]]<>"",Bitacora_2[[#This Row],[ATA DOC]], IF(Bitacora_2[[#This Row],[Clase Expedición]]="AIR",Bitacora_2[[#This Row],[ETD Real]], IF(AND(Bitacora_2[[#This Row],[Clase Expedición]]="SEA",Bitacora_2[[#This Row],[Mercado]]="LATAM"), Bitacora_2[[#This Row],[ETD Real]]+3, IF(AND(Bitacora_2[[#This Row],[Clase Expedición]]="SEA",Bitacora_2[[#This Row],[Mercado]]="EUROPE"), Bitacora_2[[#This Row],[ETD Real]]+8, IF(AND(Bitacora_2[[#This Row],[Clase Expedición]]="SEA",Bitacora_2[[#This Row],[Mercado]]="UK"), Bitacora_2[[#This Row],[ETD Real]]+11, IF(AND(Bitacora_2[[#This Row],[Clase Expedición]]="SEA",OR(Bitacora_2[[#This Row],[Mercado]]="ASIA",Bitacora_2[[#This Row],[Mercado]]="ASIA CN + HK")), Bitacora_2[[#This Row],[ETD Real]]+14, IF(AND(Bitacora_2[[#This Row],[Clase Expedición]]="SEA",OR(Bitacora_2[[#This Row],[Mercado]]="US EAST",Bitacora_2[[#This Row],[Mercado]]="US WEST",Bitacora_2[[#This Row],[Mercado]]="US SOUTH")), Bitacora_2[[#This Row],[ETD Real]]+8,""))))))) -> 46182 | V9: 46177 | W9: 46182 | X9: =IF(OR(Bitacora_2[[#This Row],[ETD Real]]="",Bitacora_2[[#This Row],[ETD Doc]]=""),"",Bitacora_2[[#This Row],[ETD Doc]]-Bitacora_2[[#This Row],[ETD Real]]) -> -12 | Y9: =IF(OR(Bitacora_2[[#This Row],[ATA DOC]]="",Bitacora_2[[#This Row],[ETA Real]]=""),"",Bitacora_2[[#This Row],[ETA Real]]-Bitacora_2[[#This Row],[ATA DOC]]) -> 12 | Z9: 2393622070 | AA9: X | AB9: X | AC9: X | AD9: X | AE9: X | AH9: X | AI9: =IF(AND(OR(E9="US EAST",E9="US WEST",E9="US SOUTH"),I9="SEA",Bitacora_2[[#This Row],[ETD Real]]-TODAY()>=3,Bitacora_2[[#This Row],[ISF]]<>"X"),"Pending", IF(AND(OR(E9="US EAST",E9="US WEST",E9="US SOUTH"),I9="SEA",Bitacora_2[[#This Row],[ETD Real]]-TODAY()=2,Bitacora_2[[#This Row],[ISF]]<>"X"),"Urgente", IF(AND(OR(E9="US EAST",E9="US WEST",E9="US SOUTH"),I9="SEA",Bitacora_2[[#This Row],[ETD Real]]-TODAY()<=1,Bitacora_2[[#This Row],[ISF]]<>"X"),"Muy Urgente", IF(AND(OR(E9="US EAST",E9="US WEST",E9="US SOUTH"),I9="SEA",Bitacora_2[[#This Row],[ISF]]="X"),"Sent","")))) | AJ9: =IF(AND(OR(Bitacora_2[[#This Row],[Clase Expedición]]="AIR",Bitacora_2[[#This Row],[Clase Expedición]]="TRK")),"Complete", IF(AND(Bitacora_2[[#This Row],[Mercado]]="LATAM",COUNTA(Bitacora_2[[#This Row],[PHYTO]:[ISF]],Bitacora_2[[#This Row],[CO]])=7,Bitacora_2[[#This Row],[Clase Expedición]]<>"TRK"), "Complete", IF(AND(Bitacora_2[[#This Row],[Mercado]]="LATAM",COUNTA(Bitacora_2[[#This Row],[PHYTO]:[PL ]],Bitacora_2[[#This Row],[CO]])=6,Bitacora_2[[#This Row],[Clase Expedición]]="SEA"), "Complete", IF(AND(OR(Bitacora_2[[#This Row],[Mercado]]="EUROPE",Bitacora_2[[#This Row],[Mercado]]="UK"),COUNTA(Bitacora_2[[#This Row],[PHYTO]],Bitacora_2[[#This Row],[INVOICE]:[PL ]],Bitacora_2[[#This Row],[COI]])=5,Bitacora_2[[#This Row],[Clase Expedición]]="SEA",Bitacora_2[[#This Row],[Manejo]]="ORG"), "Complete", IF(AND(OR(Bitacora_2[[#This Row],[Mercado]]="EUROPE",Bitacora_2[[#This Row],[Mercado]]="UK"),COUNTA(Bitacora_2[[#This Row],[PHYTO]],Bitacora_2[[#This Row],[INVOICE]:[PL ]])=4,Bitacora_2[[#This Row],[Clase Expedición]]="SEA",Bitacora_2[[#This Row],[Manejo]]="CONV"), "Complete", IF(AND(OR(Bitacora_2[[#This Row],[Mercado]]="US WEST",Bitacora_2[[#This Row],[Mercado]]="US EAST",Bitacora_2[[#This Row],[Mercado]]="US SOUTH"),COUNTA(Bitacora_2[[#This Row],[PHYTO]:[ISF]],Bitacora_2[[#This Row],[CO]])=7,Bitacora_2[[#This Row],[Clase Expedición]]="SEA",Bitacora_2[[#This Row],[Exportador]]="ECHF"), "Complete", IF(AND(OR(Bitacora_2[[#This Row],[Mercado]]="US WEST",Bitacora_2[[#This Row],[Mercado]]="US EAST",Bitacora_2[[#This Row],[Mercado]]="US SOUTH"),COUNTA(Bitacora_2[[#This Row],[PHYTO]:[ISF]])=6,Bitacora_2[[#This Row],[Clase Expedición]]="SEA",Bitacora_2[[#This Row],[Exportador]]<>"ECHF"), "Complete", IF(AND(OR(Bitacora_2[[#This Row],[Mercado]]="ASIA",Bitacora_2[[#This Row],[Mercado]]="ASIA CN + HK"),COUNTA(Bitacora_2[[#This Row],[PHYTO]:[PL ]],Bitacora_2[[#This Row],[CO]])=6), "Complete","Incomplete")))))))) -> Complete | AM9: =+IF(OR(Bitacora_2[[#This Row],[Exportador]]="INVERSIONES JORDIE",Bitacora_2[[#This Row],[Exportador]]="TAL S.A."), "Tercero", "Propio") -> Propio | AN9: =IF(AND(Bitacora_2[[#This Row],[Clase Expedición]]="AIR",OR(Bitacora_2[[#This Row],[Mercado]]="US EAST",Bitacora_2[[#This Row],[Mercado]]="US WEST",Bitacora_2[[#This Row],[Mercado]]="US SOUTH")),IF(Bitacora_2[[#This Row],[ETD Doc]]<>"","Delivered","Pending"), IF(Bitacora_2[[#This Row],[Clase Expedición]]="AIR","Delivered", IF(AND(Bitacora_2[[#This Row],[ETD Doc]]="",Bitacora_2[[#This Row],[ATA DOC]]=""),"Pending", IF(AND(Bitacora_2[[#This Row],[ETD Doc]]<>"",Bitacora_2[[#This Row],[ATA DOC]]=""),"In transit", IF(AND(Bitacora_2[[#This Row],[ETD Doc]]<>"",Bitacora_2[[#This Row],[ATA DOC]]<>""),"Delivered",""))))) -> Delivered | AO9: Released | AP9: 46204 | AQ9: =IF(I9="SEA",IF(AP9="","On Hold","Released"),"") -> Released | AR9: Demora en revisión de reporte (COSCO + SAG)
A10: RH|0002TTAL S.A.ARANCONVBMOU9893760 | B10: 22 | C10: 46170 | D10: 25 | E10: US EAST | F10: USPHL | G10: PE | H10: TAL S.A. | I10: SEA | J10: ARAN | K10: CONV | L10: RH|0002T | M10: BMOU9893760 | O10: NRF TIER I | P10: CITIKOLD | Q10: SEABOARD VALOR | R10: 46174 | S10: 46188 | U10: =+IF(Bitacora_2[[#This Row],[ATA DOC]]<>"",Bitacora_2[[#This Row],[ATA DOC]], IF(Bitacora_2[[#This Row],[Clase Expedición]]="AIR",Bitacora_2[[#This Row],[ETD Real]], IF(AND(Bitacora_2[[#This Row],[Clase Expedición]]="SEA",Bitacora_2[[#This Row],[Mercado]]="LATAM"), Bitacora_2[[#This Row],[ETD Real]]+3, IF(AND(Bitacora_2[[#This Row],[Clase Expedición]]="SEA",Bitacora_2[[#This Row],[Mercado]]="EUROPE"), Bitacora_2[[#This Row],[ETD Real]]+8, IF(AND(Bitacora_2[[#This Row],[Clase Expedición]]="SEA",Bitacora_2[[#This Row],[Mercado]]="UK"), Bitacora_2[[#This Row],[ETD Real]]+11, IF(AND(Bitacora_2[[#This Row],[Clase Expedición]]="SEA",OR(Bitacora_2[[#This Row],[Mercado]]="ASIA",Bitacora_2[[#This Row],[Mercado]]="ASIA CN + HK")), Bitacora_2[[#This Row],[ETD Real]]+14, IF(AND(Bitacora_2[[#This Row],[Clase Expedición]]="SEA",OR(Bitacora_2[[#This Row],[Mercado]]="US EAST",Bitacora_2[[#This Row],[Mercado]]="US WEST",Bitacora_2[[#This Row],[Mercado]]="US SOUTH")), Bitacora_2[[#This Row],[ETD Real]]+8,""))))))) -> 46178 | V10: 46178 | W10: 46178 | X10: =IF(OR(Bitacora_2[[#This Row],[ETD Real]]="",Bitacora_2[[#This Row],[ETD Doc]]=""),"",Bitacora_2[[#This Row],[ETD Doc]]-Bitacora_2[[#This Row],[ETD Real]]) -> 4 | Y10: =IF(OR(Bitacora_2[[#This Row],[ATA DOC]]="",Bitacora_2[[#This Row],[ETA Real]]=""),"",Bitacora_2[[#This Row],[ETA Real]]-Bitacora_2[[#This Row],[ATA DOC]]) -> 10 | Z10: - | AA10: X | AB10: X | AC10: X | AD10: X | AE10: X | AF10: x | AI10: =IF(AND(OR(E10="US EAST",E10="US WEST",E10="US SOUTH"),I10="SEA",Bitacora_2[[#This Row],[ETD Real]]-TODAY()>=3,Bitacora_2[[#This Row],[ISF]]<>"X"),"Pending", IF(AND(OR(E10="US EAST",E10="US WEST",E10="US SOUTH"),I10="SEA",Bitacora_2[[#This Row],[ETD Real]]-TODAY()=2,Bitacora_2[[#This Row],[ISF]]<>"X"),"Urgente", IF(AND(OR(E10="US EAST",E10="US WEST",E10="US SOUTH"),I10="SEA",Bitacora_2[[#This Row],[ETD Real]]-TODAY()<=1,Bitacora_2[[#This Row],[ISF]]<>"X"),"Muy Urgente", IF(AND(OR(E10="US EAST",E10="US WEST",E10="US SOUTH"),I10="SEA",Bitacora_2[[#This Row],[ISF]]="X"),"Sent","")))) -> Sent | AJ10: =IF(AND(OR(Bitacora_2[[#This Row],[Clase Expedición]]="AIR",Bitacora_2[[#This Row],[Clase Expedición]]="TRK")),"Complete", IF(AND(Bitacora_2[[#This Row],[Mercado]]="LATAM",COUNTA(Bitacora_2[[#This Row],[PHYTO]:[ISF]],Bitacora_2[[#This Row],[CO]])=7,Bitacora_2[[#This Row],[Clase Expedición]]<>"TRK"), "Complete", IF(AND(Bitacora_2[[#This Row],[Mercado]]="LATAM",COUNTA(Bitacora_2[[#This Row],[PHYTO]:[PL ]],Bitacora_2[[#This Row],[CO]])=6,Bitacora_2[[#This Row],[Clase Expedición]]="SEA"), "Complete", IF(AND(OR(Bitacora_2[[#This Row],[Mercado]]="EUROPE",Bitacora_2[[#This Row],[Mercado]]="UK"),COUNTA(Bitacora_2[[#This Row],[PHYTO]],Bitacora_2[[#This Row],[INVOICE]:[PL ]],Bitacora_2[[#This Row],[COI]])=5,Bitacora_2[[#This Row],[Clase Expedición]]="SEA",Bitacora_2[[#This Row],[Manejo]]="ORG"), "Complete", IF(AND(OR(Bitacora_2[[#This Row],[Mercado]]="EUROPE",Bitacora_2[[#This Row],[Mercado]]="UK"),COUNTA(Bitacora_2[[#This Row],[PHYTO]],Bitacora_2[[#This Row],[INVOICE]:[PL ]])=4,Bitacora_2[[#This Row],[Clase Expedición]]="SEA",Bitacora_2[[#This Row],[Manejo]]="CONV"), "Complete", IF(AND(OR(Bitacora_2[[#This Row],[Mercado]]="US WEST",Bitacora_2[[#This Row],[Mercado]]="US EAST",Bitacora_2[[#This Row],[Mercado]]="US SOUTH"),COUNTA(Bitacora_2[[#This Row],[PHYTO]:[ISF]],Bitacora_2[[#This Row],[CO]])=7,Bitacora_2[[#This Row],[Clase Expedición]]="SEA",Bitacora_2[[#This Row],[Exportador]]="ECHF"), "Complete", IF(AND(OR(Bitacora_2[[#This Row],[Mercado]]="US WEST",Bitacora_2[[#This Row],[Mercado]]="US EAST",Bitacora_2[[#This Row],[Mercado]]="US SOUTH"),COUNTA(Bitacora_2[[#This Row],[PHYTO]:[ISF]])=6,Bitacora_2[[#This Row],[Clase Expedición]]="SEA",Bitacora_2[[#This Row],[Exportador]]<>"ECHF"), "Complete", IF(AND(OR(Bitacora_2[[#This Row],[Mercado]]="ASIA",Bitacora_2[[#This Row],[Mercado]]="ASIA CN + HK"),COUNTA(Bitacora_2[[#This Row],[PHYTO]:[PL ]],Bitacora_2[[#This Row],[CO]])=6), "Complete","Incomplete")))))))) -> Complete | AM10: =+IF(OR(Bitacora_2[[#This Row],[Exportador]]="INVERSIONES JORDIE",Bitacora_2[[#This Row],[Exportador]]="TAL S.A."), "Tercero", "Propio") -> Tercero | AN10: =IF(AND(Bitacora_2[[#This Row],[Clase Expedición]]="AIR",OR(Bitacora_2[[#This Row],[Mercado]]="US EAST",Bitacora_2[[#This Row],[Mercado]]="US WEST",Bitacora_2[[#This Row],[Mercado]]="US SOUTH")),IF(Bitacora_2[[#This Row],[ETD Doc]]<>"","Delivered","Pending"), IF(Bitacora_2[[#This Row],[Clase Expedición]]="AIR","Delivered", IF(AND(Bitacora_2[[#This Row],[ETD Doc]]="",Bitacora_2[[#This Row],[ATA DOC]]=""),"Pending", IF(AND(Bitacora_2[[#This Row],[ETD Doc]]<>"",Bitacora_2[[#This Row],[ATA DOC]]=""),"In transit", IF(AND(Bitacora_2[[#This Row],[ETD Doc]]<>"",Bitacora_2[[#This Row],[ATA DOC]]<>""),"Delivered",""))))) -> Delivered | AO10: Released | AP10: 46185 | AQ10: =IF(I10="SEA",IF(AP10="","On Hold","Released"),"") -> Released
A11: PO00000050909TTAL S.A.ARANCONVSZLU9302534 | B11: 22 | C11: 46171 | D11: 25 | E11: US EAST | F11: USPHL | G11: PE | H11: TAL S.A. | I11: SEA | J11: ARAN | K11: CONV | L11: PO00000050909T | M11: SZLU9302534 | O11: NRF TIER I | P11: CITIKOLD | Q11: SEABOARD VALOR | R11: 46177 | S11: 46188 | U11: =+IF(Bitacora_2[[#This Row],[ATA DOC]]<>"",Bitacora_2[[#This Row],[ATA DOC]], IF(Bitacora_2[[#This Row],[Clase Expedición]]="AIR",Bitacora_2[[#This Row],[ETD Real]], IF(AND(Bitacora_2[[#This Row],[Clase Expedición]]="SEA",Bitacora_2[[#This Row],[Mercado]]="LATAM"), Bitacora_2[[#This Row],[ETD Real]]+3, IF(AND(Bitacora_2[[#This Row],[Clase Expedición]]="SEA",Bitacora_2[[#This Row],[Mercado]]="EUROPE"), Bitacora_2[[#This Row],[ETD Real]]+8, IF(AND(Bitacora_2[[#This Row],[Clase Expedición]]="SEA",Bitacora_2[[#This Row],[Mercado]]="UK"), Bitacora_2[[#This Row],[ETD Real]]+11, IF(AND(Bitacora_2[[#This Row],[Clase Expedición]]="SEA",OR(Bitacora_2[[#This Row],[Mercado]]="ASIA",Bitacora_2[[#This Row],[Mercado]]="ASIA CN + HK")), Bitacora_2[[#This Row],[ETD Real]]+14, IF(AND(Bitacora_2[[#This Row],[Clase Expedición]]="SEA",OR(Bitacora_2[[#This Row],[Mercado]]="US EAST",Bitacora_2[[#This Row],[Mercado]]="US WEST",Bitacora_2[[#This Row],[Mercado]]="US SOUTH")), Bitacora_2[[#This Row],[ETD Real]]+8,""))))))) -> 46178 | V11: 46178 | W11: 46178 | X11: =IF(OR(Bitacora_2[[#This Row],[ETD Real]]="",Bitacora_2[[#This Row],[ETD Doc]]=""),"",Bitacora_2[[#This Row],[ETD Doc]]-Bitacora_2[[#This Row],[ETD Real]]) -> 1 | Y11: =IF(OR(Bitacora_2[[#This Row],[ATA DOC]]="",Bitacora_2[[#This Row],[ETA Real]]=""),"",Bitacora_2[[#This Row],[ETA Real]]-Bitacora_2[[#This Row],[ATA DOC]]) -> 10 | Z11: - | AA11: X | AB11: X | AC11: X | AD11: X | AE11: X | AF11: x | AI11: =IF(AND(OR(E11="US EAST",E11="US WEST",E11="US SOUTH"),I11="SEA",Bitacora_2[[#This Row],[ETD Real]]-TODAY()>=3,Bitacora_2[[#This Row],[ISF]]<>"X"),"Pending", IF(AND(OR(E11="US EAST",E11="US WEST",E11="US SOUTH"),I11="SEA",Bitacora_2[[#This Row],[ETD Real]]-TODAY()=2,Bitacora_2[[#This Row],[ISF]]<>"X"),"Urgente", IF(AND(OR(E11="US EAST",E11="US WEST",E11="US SOUTH"),I11="SEA",Bitacora_2[[#This Row],[ETD Real]]-TODAY()<=1,Bitacora_2[[#This Row],[ISF]]<>"X"),"Muy Urgente", IF(AND(OR(E11="US EAST",E11="US WEST",E11="US SOUTH"),I11="SEA",Bitacora_2[[#This Row],[ISF]]="X"),"Sent","")))) -> Sent | AJ11: =IF(AND(OR(Bitacora_2[[#This Row],[Clase Expedición]]="AIR",Bitacora_2[[#This Row],[Clase Expedición]]="TRK")),"Complete", IF(AND(Bitacora_2[[#This Row],[Mercado]]="LATAM",COUNTA(Bitacora_2[[#This Row],[PHYTO]:[ISF]],Bitacora_2[[#This Row],[CO]])=7,Bitacora_2[[#This Row],[Clase Expedición]]<>"TRK"), "Complete", IF(AND(Bitacora_2[[#This Row],[Mercado]]="LATAM",COUNTA(Bitacora_2[[#This Row],[PHYTO]:[PL ]],Bitacora_2[[#This Row],[CO]])=6,Bitacora_2[[#This Row],[Clase Expedición]]="SEA"), "Complete", IF(AND(OR(Bitacora_2[[#This Row],[Mercado]]="EUROPE",Bitacora_2[[#This Row],[Mercado]]="UK"),COUNTA(Bitacora_2[[#This Row],[PHYTO]],Bitacora_2[[#This Row],[INVOICE]:[PL ]],Bitacora_2[[#This Row],[COI]])=5,Bitacora_2[[#This Row],[Clase Expedición]]="SEA",Bitacora_2[[#This Row],[Manejo]]="ORG"), "Complete", IF(AND(OR(Bitacora_2[[#This Row],[Mercado]]="EUROPE",Bitacora_2[[#This Row],[Mercado]]="UK"),COUNTA(Bitacora_2[[#This Row],[PHYTO]],Bitacora_2[[#This Row],[INVOICE]:[PL ]])=4,Bitacora_2[[#This Row],[Clase Expedición]]="SEA",Bitacora_2[[#This Row],[Manejo]]="CONV"), "Complete", IF(AND(OR(Bitacora_2[[#This Row],[Mercado]]="US WEST",Bitacora_2[[#This Row],[Mercado]]="US EAST",Bitacora_2[[#This Row],[Mercado]]="US SOUTH"),COUNTA(Bitacora_2[[#This Row],[PHYTO]:[ISF]],Bitacora_2[[#This Row],[CO]])=7,Bitacora_2[[#This Row],[Clase Expedición]]="SEA",Bitacora_2[[#This Row],[Exportador]]="ECHF"), "Complete", IF(AND(OR(Bitacora_2[[#This Row],[Mercado]]="US WEST",Bitacora_2[[#This Row],[Mercado]]="US EAST",Bitacora_2[[#This Row],[Mercado]]="US SOUTH"),COUNTA(Bitacora_2[[#This Row],[PHYTO]:[ISF]])=6,Bitacora_2[[#This Row],[Clase Expedición]]="SEA",Bitacora_2[[#This Row],[Exportador]]<>"ECHF"), "Complete", IF(AND(OR(Bitacora_2[[#This Row],[Mercado]]="ASIA",Bitacora_2[[#This Row],[Mercado]]="ASIA CN + HK"),COUNTA(Bitacora_2[[#This Row],[PHYTO]:[PL ]],Bitacora_2[[#This Row],[CO]])=6), "Complete","Incomplete")))))))) -> Complete | AM11: =+IF(OR(Bitacora_2[[#This Row],[Exportador]]="INVERSIONES JORDIE",Bitacora_2[[#This Row],[Exportador]]="TAL S.A."), "Tercero", "Propio") -> Tercero | AN11: =IF(AND(Bitacora_2[[#This Row],[Clase Expedición]]="AIR",OR(Bitacora_2[[#This Row],[Mercado]]="US EAST",Bitacora_2[[#This Row],[Mercado]]="US WEST",Bitacora_2[[#This Row],[Mercado]]="US SOUTH")),IF(Bitacora_2[[#This Row],[ETD Doc]]<>"","Delivered","Pending"), IF(Bitacora_2[[#This Row],[Clase Expedición]]="AIR","Delivered", IF(AND(Bitacora_2[[#This Row],[ETD Doc]]="",Bitacora_2[[#This Row],[ATA DOC]]=""),"Pending", IF(AND(Bitacora_2[[#This Row],[ETD Doc]]<>"",Bitacora_2[[#This Row],[ATA DOC]]=""),"In transit", IF(AND(Bitacora_2[[#This Row],[ETD Doc]]<>"",Bitacora_2[[#This Row],[ATA DOC]]<>""),"Delivered",""))))) -> Delivered | AO11: Released | AP11: 46185 | AQ11: =IF(I11="SEA",IF(AP11="","On Hold","Released"),"") -> Released
A12: PO00000050870HFPEARANCONV145-11634044 | B12: 22 | C12: 46172 | D12: 23 | E12: LATAM | F12: BOG | G12: PE | H12: HFPE | I12: AIR | J12: ARAN | K12: CONV | L12: PO00000050870 | M12: 145-11634044 | N12: HORTIFRUT COLOMBIA SAS | O12: HORTIFRUT COLOMBIA | Q12: 24 | R12: 46177 | S12: 46177 | T12: HELLMANN | U12: =+IF(Bitacora_2[[#This Row],[ATA DOC]]<>"",Bitacora_2[[#This Row],[ATA DOC]], IF(Bitacora_2[[#This Row],[Clase Expedición]]="AIR",Bitacora_2[[#This Row],[ETD Real]], IF(AND(Bitacora_2[[#This Row],[Clase Expedición]]="SEA",Bitacora_2[[#This Row],[Mercado]]="LATAM"), Bitacora_2[[#This Row],[ETD Real]]+3, IF(AND(Bitacora_2[[#This Row],[Clase Expedición]]="SEA",Bitacora_2[[#This Row],[Mercado]]="EUROPE"), Bitacora_2[[#This Row],[ETD Real]]+8, IF(AND(Bitacora_2[[#This Row],[Clase Expedición]]="SEA",Bitacora_2[[#This Row],[Mercado]]="UK"), Bitacora_2[[#This Row],[ETD Real]]+11, IF(AND(Bitacora_2[[#This Row],[Clase Expedición]]="SEA",OR(Bitacora_2[[#This Row],[Mercado]]="ASIA",Bitacora_2[[#This Row],[Mercado]]="ASIA CN + HK")), Bitacora_2[[#This Row],[ETD Real]]+14, IF(AND(Bitacora_2[[#This Row],[Clase Expedición]]="SEA",OR(Bitacora_2[[#This Row],[Mercado]]="US EAST",Bitacora_2[[#This Row],[Mercado]]="US WEST",Bitacora_2[[#This Row],[Mercado]]="US SOUTH")), Bitacora_2[[#This Row],[ETD Real]]+8,""))))))) -> 46177 | X12: =IF(OR(Bitacora_2[[#This Row],[ETD Real]]="",Bitacora_2[[#This Row],[ETD Doc]]=""),"",Bitacora_2[[#This Row],[ETD Doc]]-Bitacora_2[[#This Row],[ETD Real]]) | Y12: =IF(OR(Bitacora_2[[#This Row],[ATA DOC]]="",Bitacora_2[[#This Row],[ETA Real]]=""),"",Bitacora_2[[#This Row],[ETA Real]]-Bitacora_2[[#This Row],[ATA DOC]]) | AI12: =IF(AND(OR(E12="US EAST",E12="US WEST",E12="US SOUTH"),I12="SEA",Bitacora_2[[#This Row],[ETD Real]]-TODAY()>=3,Bitacora_2[[#This Row],[ISF]]<>"X"),"Pending", IF(AND(OR(E12="US EAST",E12="US WEST",E12="US SOUTH"),I12="SEA",Bitacora_2[[#This Row],[ETD Real]]-TODAY()=2,Bitacora_2[[#This Row],[ISF]]<>"X"),"Urgente", IF(AND(OR(E12="US EAST",E12="US WEST",E12="US SOUTH"),I12="SEA",Bitacora_2[[#This Row],[ETD Real]]-TODAY()<=1,Bitacora_2[[#This Row],[ISF]]<>"X"),"Muy Urgente", IF(AND(OR(E12="US EAST",E12="US WEST",E12="US SOUTH"),I12="SEA",Bitacora_2[[#This Row],[ISF]]="X"),"Sent","")))) | AJ12: =IF(AND(OR(Bitacora_2[[#This Row],[Clase Expedición]]="AIR",Bitacora_2[[#This Row],[Clase Expedición]]="TRK")),"Complete", IF(AND(Bitacora_2[[#This Row],[Mercado]]="LATAM",COUNTA(Bitacora_2[[#This Row],[PHYTO]:[ISF]],Bitacora_2[[#This Row],[CO]])=7,Bitacora_2[[#This Row],[Clase Expedición]]<>"TRK"), "Complete", IF(AND(Bitacora_2[[#This Row],[Mercado]]="LATAM",COUNTA(Bitacora_2[[#This Row],[PHYTO]:[PL ]],Bitacora_2[[#This Row],[CO]])=6,Bitacora_2[[#This Row],[Clase Expedición]]="SEA"), "Complete", IF(AND(OR(Bitacora_2[[#This Row],[Mercado]]="EUROPE",Bitacora_2[[#This Row],[Mercado]]="UK"),COUNTA(Bitacora_2[[#This Row],[PHYTO]],Bitacora_2[[#This Row],[INVOICE]:[PL ]],Bitacora_2[[#This Row],[COI]])=5,Bitacora_2[[#This Row],[Clase Expedición]]="SEA",Bitacora_2[[#This Row],[Manejo]]="ORG"), "Complete", IF(AND(OR(Bitacora_2[[#This Row],[Mercado]]="EUROPE",Bitacora_2[[#This Row],[Mercado]]="UK"),COUNTA(Bitacora_2[[#This Row],[PHYTO]],Bitacora_2[[#This Row],[INVOICE]:[PL ]])=4,Bitacora_2[[#This Row],[Clase Expedición]]="SEA",Bitacora_2[[#This Row],[Manejo]]="CONV"), "Complete", IF(AND(OR(Bitacora_2[[#This Row],[Mercado]]="US WEST",Bitacora_2[[#This Row],[Mercado]]="US EAST",Bitacora_2[[#This Row],[Mercado]]="US SOUTH"),COUNTA(Bitacora_2[[#This Row],[PHYTO]:[ISF]],Bitacora_2[[#This Row],[CO]])=7,Bitacora_2[[#This Row],[Clase Expedición]]="SEA",Bitacora_2[[#This Row],[Exportador]]="ECHF"), "Complete", IF(AND(OR(Bitacora_2[[#This Row],[Mercado]]="US WEST",Bitacora_2[[#This Row],[Mercado]]="US EAST",Bitacora_2[[#This Row],[Mercado]]="US SOUTH"),COUNTA(Bitacora_2[[#This Row],[PHYTO]:[ISF]])=6,Bitacora_2[[#This Row],[Clase Expedición]]="SEA",Bitacora_2[[#This Row],[Exportador]]<>"ECHF"), "Complete", IF(AND(OR(Bitacora_2[[#This Row],[Mercado]]="ASIA",Bitacora_2[[#This Row],[Mercado]]="ASIA CN + HK"),COUNTA(Bitacora_2[[#This Row],[PHYTO]:[PL ]],Bitacora_2[[#This Row],[CO]])=6), "Complete","Incomplete")))))))) -> Complete | AM12: =+IF(OR(Bitacora_2[[#This Row],[Exportador]]="INVERSIONES JORDIE",Bitacora_2[[#This Row],[Exportador]]="TAL S.A."), "Tercero", "Propio") -> Propio | AN12: =IF(AND(Bitacora_2[[#This Row],[Clase Expedición]]="AIR",OR(Bitacora_2[[#This Row],[Mercado]]="US EAST",Bitacora_2[[#This Row],[Mercado]]="US WEST",Bitacora_2[[#This Row],[Mercado]]="US SOUTH")),IF(Bitacora_2[[#This Row],[ETD Doc]]<>"","Delivered","Pending"), IF(Bitacora_2[[#This Row],[Clase Expedición]]="AIR","Delivered", IF(AND(Bitacora_2[[#This Row],[ETD Doc]]="",Bitacora_2[[#This Row],[ATA DOC]]=""),"Pending", IF(AND(Bitacora_2[[#This Row],[ETD Doc]]<>"",Bitacora_2[[#This Row],[ATA DOC]]=""),"In transit", IF(AND(Bitacora_2[[#This Row],[ETD Doc]]<>"",Bitacora_2[[#This Row],[ATA DOC]]<>""),"Delivered",""))))) -> Delivered | AQ12: =IF(I12="SEA",IF(AP12="","On Hold","Released"),"")
